[2023-04-11T12:28:32.730+0000] {taskinstance.py:1165} INFO - Dependencies all met for <TaskInstance: extr_proc_aug_pipl.processing_data scheduled__2022-12-25T10:30:00+00:00 [queued]>
[2023-04-11T12:28:32.742+0000] {taskinstance.py:1165} INFO - Dependencies all met for <TaskInstance: extr_proc_aug_pipl.processing_data scheduled__2022-12-25T10:30:00+00:00 [queued]>
[2023-04-11T12:28:32.742+0000] {taskinstance.py:1362} INFO - 
--------------------------------------------------------------------------------
[2023-04-11T12:28:32.742+0000] {taskinstance.py:1363} INFO - Starting attempt 1 of 4
[2023-04-11T12:28:32.742+0000] {taskinstance.py:1364} INFO - 
--------------------------------------------------------------------------------
[2023-04-11T12:28:32.757+0000] {taskinstance.py:1383} INFO - Executing <Task(BashOperator): processing_data> on 2022-12-25 10:30:00+00:00
[2023-04-11T12:28:32.761+0000] {standard_task_runner.py:55} INFO - Started process 553 to run task
[2023-04-11T12:28:32.764+0000] {standard_task_runner.py:82} INFO - Running: ['***', 'tasks', 'run', 'extr_proc_aug_pipl', 'processing_data', 'scheduled__2022-12-25T10:30:00+00:00', '--job-id', '5458', '--raw', '--subdir', 'DAGS_FOLDER/extr_processing_augmentation.py', '--cfg-path', '/tmp/tmpur9u2anm']
[2023-04-11T12:28:32.765+0000] {standard_task_runner.py:83} INFO - Job 5458: Subtask processing_data
[2023-04-11T12:28:32.781+0000] {logging_mixin.py:120} WARNING - /home/***/.local/lib/python3.7/site-packages/***/configuration.py:545 DeprecationWarning: The sql_alchemy_conn option in [core] has been moved to the sql_alchemy_conn option in [database] - the old setting has been used, but please update your config.
[2023-04-11T12:28:32.834+0000] {task_command.py:376} INFO - Running <TaskInstance: extr_proc_aug_pipl.processing_data scheduled__2022-12-25T10:30:00+00:00 [running]> on host 0961b7a3874f
[2023-04-11T12:28:32.906+0000] {taskinstance.py:1592} INFO - Exporting the following env vars:
AIRFLOW_CTX_DAG_EMAIL=***@***.com
AIRFLOW_CTX_DAG_OWNER=***
AIRFLOW_CTX_DAG_ID=extr_proc_aug_pipl
AIRFLOW_CTX_TASK_ID=processing_data
AIRFLOW_CTX_EXECUTION_DATE=2022-12-25T10:30:00+00:00
AIRFLOW_CTX_TRY_NUMBER=1
AIRFLOW_CTX_DAG_RUN_ID=scheduled__2022-12-25T10:30:00+00:00
[2023-04-11T12:28:32.908+0000] {subprocess.py:63} INFO - Tmp dir root location: 
 /tmp
[2023-04-11T12:28:32.908+0000] {subprocess.py:75} INFO - Running command: ['/bin/bash', '-c', 'sleep 5']
[2023-04-11T12:28:32.918+0000] {subprocess.py:86} INFO - Output:
[2023-04-11T12:28:34.260+0000] {local_task_job.py:87} ERROR - Received SIGTERM. Terminating subprocesses
[2023-04-11T12:28:34.271+0000] {process_utils.py:133} INFO - Sending Signals.SIGTERM to group 553. PIDs of all processes in the group: [555, 553]
[2023-04-11T12:28:34.272+0000] {process_utils.py:84} INFO - Sending the signal Signals.SIGTERM to group 553
[2023-04-11T12:28:34.272+0000] {taskinstance.py:1562} ERROR - Received SIGTERM. Terminating subprocesses.
[2023-04-11T12:28:34.273+0000] {subprocess.py:104} INFO - Sending SIGTERM signal to process group
[2023-04-11T12:28:34.301+0000] {taskinstance.py:1851} ERROR - Task failed with exception
Traceback (most recent call last):
  File "/home/airflow/.local/lib/python3.7/site-packages/airflow/operators/bash.py", line 191, in execute
    cwd=self.cwd,
  File "/home/airflow/.local/lib/python3.7/site-packages/airflow/hooks/subprocess.py", line 91, in run_command
    for raw_line in iter(self.sub_process.stdout.readline, b''):
  File "/home/airflow/.local/lib/python3.7/site-packages/airflow/models/taskinstance.py", line 1564, in signal_handler
    raise AirflowException("Task received SIGTERM signal")
airflow.exceptions.AirflowException: Task received SIGTERM signal
[2023-04-11T12:28:34.308+0000] {taskinstance.py:1406} INFO - Marking task as UP_FOR_RETRY. dag_id=extr_proc_aug_pipl, task_id=processing_data, execution_date=20221225T103000, start_date=20230411T122832, end_date=20230411T122834
[2023-04-11T12:28:34.353+0000] {standard_task_runner.py:105} ERROR - Failed to execute job 5458 for task processing_data (Task received SIGTERM signal; 553)
[2023-04-11T12:28:34.389+0000] {process_utils.py:79} INFO - Process psutil.Process(pid=555, status='terminated', started='12:28:31') (555) terminated with exit code None
[2023-04-11T12:28:34.390+0000] {process_utils.py:79} INFO - Process psutil.Process(pid=553, status='terminated', exitcode=1, started='12:28:31') (553) terminated with exit code 1
[2023-04-11T12:28:34.390+0000] {local_task_job.py:164} INFO - Task exited with return code 143
[2023-04-11T12:28:34.497+0000] {local_task_job.py:273} INFO - 0 downstream tasks scheduled from follow-on schedule check
